Workbook

Sheet Lists of values
A1: Manufacturer | C1: Sensor type | D1: Chroma | E1: Interface | F1: Power supply | G1: Lens mount | H1: Quantum Eff.
A2: AXIS | C2: CMOS | D2: Mono | E2: GigE | F2: PoE | G2: C-Mount | H2: IR
A3: Basler | C3: Progressive CCD | D3: Color | E3: USB3 | F3: 12-24VDC | G3: CS-Mount | H3: XUV
A4: Flir | C4: Progressive Scan CMOS | E4: USB2 | F4: PoE, 12-24VDC | G4: S-Mount | H4: MIR
A5: Thorlabs | C5: CCD | E5: http | F5: USB
A6: iDS | C6: Pyroelectric | E6: IEEE 802.3 1000baseT | F6: PoE, 12VDC
A7: AXIS | C7: Semiconductor | E7: IEEE 1394b - 800 Mb/s | F7: 23-28VDC
A8: Andor Oxford Instruments | C8: Thermal | E8: Micro BNC | F8: 8-36VDC
A9: Phasics | C9: Photodiode | F9: 12V
A10: Optocraft | C10: BeamTrack | F10: Power via GPIO
A11: Ophir | F11: 220 V AC
A12: Imperx | F12: PoCXP
A13: Allied Vision Technologies
A14: Lucid Vision Labs
A15: Emergent Vision Technologies
A16: Fluke
A17: Greateyes
A18: Kaya Instruments
A19: NIT
A20: Teledyne Photometrics
A21: Teledyne Princeton Instruments
A22: Smartek Vision
A23: Ximea
A24: LASER COMPONENTS GmbH
A25: Coherent

Sheet Catalogue properties
A1: Property name | B1: Catalogue Item name | C1: Catalogue item description | D1: Manufacturer | E1: Manufacturer part/catalog number | F1: ManufacturerURL
A2: Property type | B2: Text | C2: TextArea | D2: External List | E2: Text | F2: Text
A3: List of values (; separated)
A4: Default value
A5: Allow custom value
A6: Unit type
A7: Category group | B7: General properties | C7: General properties | D7: General properties | E7: General properties | F7: General properties

Sheet Beam characterization
A1: Property name | B1: Category | C1: Parent category
A2: Property type | B2: text | C2: text
A3: List of values (; separated)
A4: Default value | B4: Beam characterization
A5: Allow custom value
A6: Unit type
A7: Category group | B7: General properties | C7: General properties

Sheet Cameras
A1: Property name | B1: Category | C1: Parent category | D1: Sensor Type | E1: Resolution | F1: Frame Rate at full resolution | G1: Chroma | H1: Interface | I1: Power supply | J1: Lens mount | K1: Pixel bit depth | L1: Triggerable | M1: Quantum efficiency
A2: Property type | B2: text | C2: text | D2: List | E2: Number | F2: Number | G2: List | H2: List | I2: List | J2: List | K2: Number | L2: List | M2: List
A3: List of values (; separated) | D3: CMOS | G3: Mono; Color | H3: GigE, USB3, | I3: PoE, 12-24VDC | J3: C-mount | L3: Yes; No
A4: Default value | B4: Cameras | C4: Beam characterization
A5: Allow custom value | D5: =TRUE() -> 1 | E5: =TRUE() -> 1 | F5: =TRUE() -> 1 | I5: 1
A6: Unit type | E6: MP | F6: fps | K6: bit
A7: Category group | B7: General properties | C7: General properties | D7: Sensor | E7: Sensor | F7: Sensor | G7: Sensor | H7: Camera data | I7: Camera data | J7: Housing | K7: Sensor | L7: Camera Data | M7: Sensor

Sheet Catalogue items
A1: Cameras
A2: =CONCATENATE('Catalogue properties'!B1," [",'Catalogue properties'!B6,"]") -> Catalogue Item name [] | B2: =CONCATENATE('Catalogue properties'!C1," [",'Catalogue properties'!C6,"]") -> Catalogue item description [] | C2: =CONCATENATE('Catalogue properties'!D1," [",'Catalogue properties'!D6,"]") -> Manufacturer [] | D2: =CONCATENATE('Catalogue properties'!E1," [",'Catalogue properties'!E6,"]") -> Manufacturer part/catalog number [] | E2: =CONCATENATE('Catalogue properties'!F1," [",'Catalogue properties'!F6,"]") -> ManufacturerURL [] | F2: =CONCATENATE(Cameras!D1," [",Cameras!D6,"]") -> Sensor Type [] | G2: =CONCATENATE(Cameras!E1," [",Cameras!E6,"]") -> Resolution [MP] | H2: =CONCATENATE(Cameras!F1," [",Cameras!F6,"]") -> Frame Rate at full resolution [fps] | I2: =CONCATENATE(Cameras!G1," [",Cameras!G6,"]") -> Chroma [] | J2: =CONCATENATE(Cameras!H1," [",Cameras!H6,"]") -> Interface [] | K2: =CONCATENATE(Cameras!I1," [",Cameras!I6,"]") -> Power supply [] | L2: =CONCATENATE(Cameras!J1," [",Cameras!J6,"]") -> Lens mount [] | M2: =CONCATENATE(Cameras!K1," [",Cameras!K6,"]") -> Pixel bit depth [bit] | ... O2: =CONCATENATE(Cameras!M1," [",Cameras!M6,"]") -> Quantum efficiency [] | P2: EUN
A3: Basler acA1440-73gm | B3: The Basler acA1440-73gm GigE camera with the Sony IMX273 CMOS sensor delivers 73 frames per second at 1.6 MP resolution. | C3: Basler | D3: acA1440-73gm | E3: https://www.baslerweb.com/en/products/cameras/area-scan-cameras/ace/aca1440-73gm/ | F3: CMOS | G3: 1.6 | H3: 73 | I3: Mono | J3: GigE | K3: PoE, 12-24VDC | L3: C-Mount | M3: 12 | N3: Yes
A4: Basler acA1920-50gm | B4: The Basler acA1920-50gm GigE camera with the Sony IMX174 CMOS sensor delivers 50 frames per second at 2.3 MP resolution. | C4: Basler | D4: acA1920-50gm | E4: https://www.baslerweb.com/en/products/cameras/area-scan-cameras/ace/aca1920-50gm/ | F4: CMOS | G4: 2.3 | H4: 50 | I4: Mono | J4: GigE | K4: PoE, 12-24VDC | L4: C-Mount | M4: 12 | N4: Yes | P4: 21050063 | Q4: 19110638
A5: Basler acA2040-35gm | B5: The Basler acA2040-35gm GigE camera with the Sony IMX265 CMOS sensor delivers 36 frames per second at 3.2 MP Resolution. | C5: Basler | D5: acA2040-35gm | E5: https://www.baslerweb.com/en/products/cameras/area-scan-cameras/ace/aca2040-35gm/ | F5: CMOS | G5: 3 | H5: 36 | I5: Mono | J5: GigE | K5: PoE, 12-24VDC | L5: C-Mount | M5: 12 | N5: Yes
A6: BFLY-PGE-12A2M-CS | B6: The Blackfly® camera line combines Sony CCD, Aptina, e2v, and Sharp sensors with a host of unique features. For FLIR area scan cameras with the latest sensors and most advanced feature sets, please refer to our Blackfly S and Oryx camera families. | C6: Flir | D6: BFLY-PGE-12A2M-CS | E6: https://www.flir.com/products/blackfly-gige/?model=BFLY-PGE-12A2M-CS | F6: CMOS | G6: 1.2 | H6: 52 | I6: Mono | J6: GigE | K6: PoE | L6: CS-Mount | M6: 12 | N6: Yes
A7: BFLY-PGE-31S4M-C | B7: Model: BFLY-PGE-31S4M-C: 3.2 MP, 35 FPS, Sony IMX265, Mono | C7: Flir | D7: BFLY-PGE-31S4M-C | E7: https://www.flir.eu/products/blackfly-gige/?model=BFLY-PGE-31S4M-C | F7: CMOS | G7: 3.2 | H7: 35 | I7: Mono | J7: GigE | K7: PoE | L7: C-Mount | M7: 12 | N7: Yes
A8: AXIS M1014 | C8: AXIS | D8: AXIS M1014 | E8: https://www.axis.com/products/axis-m1014/support | F8: CMOS | G8: 1 | H8: 30 | I8: Color | J8: http | K8: 12-24VDC
A9: AXIS M1045-LW | C9: AXIS | D9: AXIS M1045-LW | E9: https://www.axis.com/products/axis-m1045-lw | F9: CMOS | G9: 2 | H9: 30 | I9: Color | J9: http
A10: Andor Newton DU920P-BN | B10: The high-end USB 2.0 Newton CCD series brings together Andor’s ultra fast, low-noise electronics platform and market-leading deep thermo-electric cooling to -100°C, complemented by Andor’s UltravacTM technology with its un-matched reliability track record in the scientific and industrial communities | C10: Andor Oxford Instruments | D10: Andor Newton DU920P-BN | E10: https://andor.oxinst.com/products/newton-ccd-and-emccd-cameras/newton-920 | I10: Mono | J10: USB2
A11: Grasshopper3 GS3-PGE-23S6M | B11: Model: GS3-PGE-23S6M-C: 2.3 MP, 48 FPS, Sony IMX174, Mono | C11: Flir | D11: GS3-PGE-23S6M-C | E11: https://www.flir.eu/products/grasshopper3-gige/?model=GS3-PGE-23S6M-C | F11: CMOS | G11: 2.3 | H11: 48 | I11: Mono | J11: GigE | K11: PoE, 12-24VDC | L11: C-Mount | M11: 12 | N11: Yes
A12: Thorlabs, BC106-VIS | C12: Thorlabs | D12: BC106-VIS | E12: https://www.thorlabs.com/thorproduct.cfm?partnumber=BC106-VIS | F12: Progressive CCD | G12: 1.2 | H12: 10 | I12: Mono | J12: USB2
A13: iDS UI-3060 | B13: The UI-3060CP with Sony's 2.3 MP sensor IMX174 (1936 x 1216 px) sets a new standard in terms of light sensitivity, dynamic range and color reproduction. | C13: iDS | D13: UI-3060CP | E13: https://en.ids-imaging.com/store/ui-3060cp-rev-2.html | F13: CMOS | G13: 2.35 | H13: 166 | I13: Color | J13: USB3 | L13: C-Mount
A14: Bobcat B0610 | B14: The B0610 is an advanced high-speed progressive scan, fully programmable CCD camera designed for imaging applications that require high quality images with powerful features and flexibility. The camera has a small size, light weight, and is built around the TRUESENSE KAI-0340S Interline Transfer CCD image sensor which provides an image resolution of 640 x 480 and delivers up to 136 frames per second with a 1/3" optical format. B0610 is available with Camera Link® Base (PoCL), GigE Vision®, PoE and CoaXPress output. | C14: Imperx | D14: B0610 | E14: https://www.imperx.com/ccd-cameras/b0610/ | F14: Progressive CCD | G14: 0.3 | H14: 110 | I14: Color | J14: GigE | K14: PoE | L14: C-Mount | M14: 12 | N14: Yes | P14: 15100501
A15: IDS UI-1252LE | B15: The UI-1252LE with the e2v CMOS sensor with 2 megapixel resolution is an especially high-performance and versatile industrial camera (EV76C570). It has one of the most sensitive sensors in the IDS product portfolio and it is available in monochrome and color versions. Besides its outstanding sensitivity to light in CCD quality, the camera also has a range of other distinctive features: The sensor allows you to switch between various shutter modes, which allow you to capture sharp images of moving objects or extremely low-noise, high-contrast images. | C15: iDS | D15: UI-1252LE-M:AB00336 | E15: https://en.ids-imaging.com/store/ui-1252le.html | F15: CMOS | G15: 1.92 | H15: 17.6 | I15: Mono | J15: USB2 | K15: USB | M15: 10 | P15: 14060088-92
A16: Manta G-125B/C | B16: Manta is Allied Vision’s most versatile GigE Vision camera series. It provides the largest choice of image sensors and its advanced feature set simplifies the setup of multi-camera applications. With its modular hardware concept, Manta offers nearly endless configuration possibilities to adapt the camera to your application. | C16: Allied Vision Technologies | D16: G-125B/C | E16: https://www.alliedvision.com/en/camera-selector/detail/manta/g-125/ | F16: Progressive CCD | G16: 1.2 | H16: 30 | I16: Color | J16: IEEE 802.3 1000baseT | K16: PoE, 12VDC | L16: CS-Mount | M16: 12 | N16: Yes | P16: 14060560-64
A17: Andor iKon-L SO | B17: Andor's iKon-L SO is a revolutionary large area CCD platform, offering back illuminated (> 90% QE) full frame sensors up to 4MPixel(2k x 2k), 1 MHz readoutand unparalleled priority TE cooling down to –100°C. | C17: Andor Oxford Instruments | D17: iKon-L SO | E17: https://andor.oxinst.com/products/high-energy-detection/ikon-l-so | F17: Progressive CCD | G17: 4.2 | H17: 0.953 | I17: Mono | J17: USB2 | M17: 16 | P17: 16031005 | Q17: 16031006
A18: Basler acA1600-20gm | B18: The Basler GigE camera with the Sony ICX274 CMOS sensor delivers 20 frames per second at 2 MP resolution. | C18: Basler | D18: acA1600-20gm | E18: https://www.baslerweb.com/en/service/search/?q=acA1600-20gm | F18: CMOS | G18: 2 | H18: 20 | I18: Mono | J18: GigE | K18: PoE, 12VDC | L18: C-Mount | M18: 12 | N18: Yes | P18: 22020076-79 | Q18: 20110914-26 | R18: 19030037-41 | S18: 18120001-19 | T18: 18061282-1301 | U18: 15050032
A19: Basler acA3800-10gc | B19: The Basler acA3800-10gc GigE camera with the ON Semiconductor MT9J003 CMOS sensor delivers 10 frames per second at 10 MP resolution. | C19: Basler | D19: acA3800-10gc | E19: https://www.baslerweb.com/en/products/cameras/area-scan-cameras/ace/aca3800-10gc/ | F19: CMOS | G19: 10 | H19: 10 | I19: Color | J19: GigE | K19: PoE, 12-24VDC | L19: C-Mount | M19: 12 | N19: Yes | P19: 22010043-52 | Q19: 17110256-65 | R19: 15110249
A20: Basler acA2440-20gm | B20: The Basler acA2440-20gm GigE camera with the Sony IMX264 CMOS sensor delivers 23 frames per second at 5.0 MP Resolution. | C20: Basler | D20: acA2440-20gm | E20: https://www.baslerweb.com/en/products/cameras/area-scan-cameras/ace/aca2440-20gm/ | F20: CMOS | G20: 5 | H20: 23 | I20: Mono | J20: GigE | K20: PoE, 12-24VDC | L20: C-Mount | M20: 12 | N20: Yes | P20: 21050479
A21: Basler acA2000-50gc | B21: The Basler acA2000-50gc (CS-Mount) GigE camera with the ams CMV2000 CMOS sensor delivers 50 frames per second at 2 MP resolution. | C21: Basler | D21: acA2000-50gc | E21: https://www.baslerweb.com/en/products/cameras/area-scan-cameras/ace/aca2000-50gc-cs-mount/ | F21: CMOS | G21: 2 | H21: 50 | I21: Color | J21: GigE | K21: PoE, 12VDC | L21: CS-Mount | M21: 12 | N21: Yes | P21: 21050066
A22: Basler acA2000-50gm | B22: The Basler acA2000-50gm GigE camera with the ams CMV2000 CMOS sensor delivers 50 frames per second at 2 MP resolution. | C22: Basler | D22: acA2000-50gm | E22: https://www.baslerweb.com/en/products/cameras/area-scan-cameras/ace/aca2000-50gm/ | F22: CMOS | G22: 2 | H22: 50 | I22: Mono | J22: GigE | K22: PoE, 12VDC | L22: C-Mount | M22: 12 | N22: Yes | P22: 21050065
A23: Basler acA1920-48gm | B23: The Basler acA1920-48gm GigE camera with the ON Semiconductor PYTHON 2000 CMOS sensor delivers 50 frames per second at 2.3 MP resolution. | C23: Basler | D23: acA1920-48gm | E23: https://www.baslerweb.com/en/products/cameras/area-scan-cameras/ace/aca1920-48gm/ | F23: CMOS | G23: 2.3 | H23: 50 | I23: Mono | J23: GigE | K23: PoE, 12-24VDC | L23: C-Mount | M23: 10 | N23: Yes | P23: 21050064 | Q23: 19110638
A24: Basler acA720-290gm | B24: The Basler acA720-290gm GigE camera with the Sony IMX287 CMOS sensor delivers 291 frames per second at VGA resolution. | C24: Basler | D24: acA720-290gm | E24: https://www.baslerweb.com/en/products/cameras/area-scan-cameras/ace/aca720-290gm/ | F24: CMOS | G24: VGA | H24: 291 | I24: Mono | J24: GigE | K24: PoE, 12-24VDC | L24: C-Mount | M24: 12 | N24: Yes | P24: 20100343-46
A25: Basler acA5472-5gm | B25: The Basler acA5472-5gm GigE camera with the Sony IMX183 CMOS sensor delivers 5 frames per second at 20.0 MP Resolution. | C25: Basler | D25: acA5472-5gm | E25: https://www.baslerweb.com/en/products/cameras/area-scan-cameras/ace/aca5472-5gm/ | F25: CMOS | G25: 20 | H25: 5 | I25: Mono | J25: GigE | K25: PoE, 12-24VDC | L25: C-Mount | M25: 12 | N25: Yes | P25: 20100339 | Q25: 20100336
A26: Basler acA2500-20gm | B26: The Basler acA2500-20gm GigE camera with the ON Semiconductor PYTHON 5000 CMOS sensor delivers 21 frames per second at 5 MP resolution. | C26: Basler | D26: acA2500-20gm | E26: https://www.baslerweb.com/en/products/cameras/area-scan-cameras/ace/aca2500-20gm/ | F26: CMOS | G26: 5 | H26: 21 | I26: Mono | J26: GigE | K26: PoE, 12-24VDC | L26: C-Mount | M26: 10 | N26: Yes | P26: 20100337 | Q26: 20100335
A27: Basler acA1920-40um | B27: The Basler acA1920-40um USB 3.0 camera with the Sony IMX249 CMOS sensor delivers 41 frames per second at 2.3 MP resolution. | C27: Basler | D27: acA1920-40um | E27: https://www.baslerweb.com/en/products/cameras/area-scan-cameras/ace/aca1920-40um/ | F27: CMOS | G27: 2.3 | H27: 41 | I27: Mono | J27: USB3 | K27: USB | L27: C-Mount | M27: 12 | N27: Yes | P27: 20060082-86
A28: Basler acA2440-20gc | B28: The Basler acA2440-20gc GigE camera with the Sony IMX264 CMOS sensor delivers 23 frames per second at 5.0 MP Resolution. | C28: Basler | D28: acA2440-20gc | E28: https://www.baslerweb.com/en/products/cameras/area-scan-cameras/ace/aca2440-20gc/ | F28: CMOS | G28: 5 | H28: 23 | I28: Color | J28: GigE | K28: PoE, 12-24VDC | L28: C-Mount | M28: 12 | N28: Yes | P28: 19110596
A29: Basler daA2500-14um | B29: The Basler daA2500-14um (S-Mount) USB 3.0 camera with the ON Semiconductor MT9P031 CMOS sensor delivers 14 frames per second at 5 MP resolution. This model comes with a S-mount. | C29: Basler | D29: daA2500-14um | E29: https://www.baslerweb.com/en/products/cameras/area-scan-cameras/dart/daa2500-14um-s-mount/ | F29: CMOS | G29: 5 | H29: 14 | I29: Mono | J29: USB3 | K29: USB | L29: S-Mount | M29: 12 | N29: Yes | P29: 16110086 | Q29: 16110087
A30: Basler acA2040-35gc | B30: The Basler acA2040-35gc GigE camera with the Sony IMX265 CMOS sensor delivers 36 frames per second at 3.2 MP Resolution. | C30: Basler | D30: acA2040-35gc | E30: https://www.baslerweb.com/en/products/cameras/area-scan-cameras/ace/aca2040-35gc/ | F30: CMOS | G30: 3 | H30: 36 | I30: Color | J30: GigE | K30: PoE, 12-24VDC | L30: C-Mount | M30: 12 | N30: Yes | P30: 21050336-38
A31: Basler acA2040-25gm | B31: The Basler acA2040-25gm GigE camera with the ams CMV4000 CMOS sensor delivers 25 frames per second at 4 MP resolution. | C31: Basler | D31: acA2040-25gm | E31: https://www.baslerweb.com/en/products/cameras/area-scan-cameras/ace/aca2040-35gc/ | F31: CMOS | G31: 4 | H31: 25 | I31: Mono | J31: GigE | K31: PoE, 12VDC | L31: C-Mount | N31: Yes
A32: Basler acA3800-10gm | B32: he Basler acA3800-10gm GigE camera with the ON Semiconductor MT9J003 CMOS sensor delivers 10 frames per second at 10 MP resolution. | C32: Basler | D32: acA3800-10gm | E32: https://www.baslerweb.com/en/products/cameras/area-scan-cameras/ace/aca3800-10gm/ | F32: CMOS | G32: 10 | H32: 10 | I32: Mono | J32: GigE | K32: PoE, 12-24VDC | L32: C-Mount | M32: 12 | N32: Yes | P32: 15110248
A33: AXIS-PX | B33: AXIS-PX is the only commercial x-ray streak camera that can streak 450 spatial resolution points (18 mm slit) with a time resolution of 700 fs (measured at FWHM). | C33: AXIS | D33: AXIS-PX | E33: https://www.axis-photon.com/streak-camera/axis-px-subpicosecond-x-ray-streak-camera/ | K33: 23-28VDC | P33: 16010127 | Q33: 16010125
A34: Manta G-507B | B34: Allied Vision Manta G-507B Monochrome CMOS PoE Camera | C34: Allied Vision Technologies | D34: G-507B | E34: https://www.edmundoptics.com/p/allied-vision-manta-g-507b-monochrome-cmos-poe-camera/40123/ | F34: Progressive Scan CMOS | G34: 5.1 | H34: 23.7 | I34: Mono | J34: GigE | K34: PoE | L34: C-Mount | M34: 12 | N34: Yes | P34: 20070233 | Q34: 19100574 | R34: 21010056 | S34: 21010057 | T34: 21050455-57
A35: Manta G-319B | B35: Allied Vision Manta G-319B Monochrome CMOS PoE Camera | C35: Allied Vision Technologies | D35: G-319B | E35: https://www.edmundoptics.com/p/allied-vision-manta-g-319b-monochrome-cmos-poe-camera/40121/ | F35: Progressive Scan CMOS | G35: 3.2 | H35: 37.6 | I35: Mono | J35: GigE | K35: PoE | L35: C-Mount | M35: 12 | N35: Yes | P35: 20070232
A36: Manta G-235B | B36: Modular machine vision camera with GigE Vision interface | C36: Allied Vision Technologies | D36: G-235B | E36: https://www.alliedvision.com/en/camera-selector/detail/manta/g-235/ | F36: CMOS | G36: 2.4 | H36: 50 | I36: Mono | J36: IEEE 802.3 1000baseT | K36: PoE | L36: C-Mount | M36: 12 | N36: Yes | P36: 21080009-12 | Q36: 20110637 | R36: 19080327-35 | S36: 19080325
A37: Manta G-125B | B37: Modular machine vision camera with GigE Vision interface | C37: Allied Vision Technologies | D37: G-125B | E37: https://www.alliedvision.com/en/camera-selector/detail/manta/g-125/ | F37: Progressive CCD | G37: 1.2 | H37: 31 | I37: Mono | J37: IEEE 802.3 1000baseT | K37: PoE | L37: C-Mount | M37: 12 | N37: Yes | P37: 21040166
A38: Guppy PRO F-503 | B38: Ultra-compact industrial camera with IEEE 1394b interface | C38: Allied Vision Technologies | D38: Guppy PRO F-503 | E38: https://www.alliedvision.com/en/camera-selector/detail/guppy-pro/f-503/ | F38: CMOS | G38: 5 | H38: 13 | I38: Mono | J38: IEEE 1394b - 800 Mb/s | K38: 8-36VDC | L38: C-Mount | M38: 12 | N38: Yes | P38: 17030397-400
A39: Lucid Vision Labs Phoenix PHX200S-MC | B39: Lucid Vision Labs Phoenix™ PHX200S-MC, Sony IMX183, 20.0 MP, Monochrome Camera | C39: Lucid Vision Labs | D39: PHX200S-CC | E39: https://www.edmundoptics.com/p/phoenixt-phx200s-1-monochrome-gige-camera/40104/ | F39: Progressive Scan CMOS | G39: 20 | H39: 6 | I39: Mono | J39: GigE | K39: PoE, 12-24VDC | L39: C-Mount | M39: 12 | N39: Yes | P39: 21050316-18
A40: Lucid Vision Labs Phoenix PHX200S-CC | B40: Lucid Vision Labs Phoenix™ PHX200S-CC, Sony IMX183, 20.0 MP, Color Camera | C40: Lucid Vision Labs | D40: PHX200S-MC | E40: https://www.edmundoptics.com/p/phoenixt-phx200s-1-color-gige-camera/40105/ | F40: Progressive Scan CMOS | G40: 20 | H40: 6 | I40: Color | J40: GigE | K40: PoE, 12-24VDC | L40: C-Mount | M40: 12 | N40: Yes | P40: 19100202
...

Sheet Wavefront Sensors
A1: Property name | B1: Category | C1: Parent category | D1: Wavelength range minimum | E1: Wavelength range maximum | F1: Accuracy | G1: Resolution | H1: Vacum compatible
A2: Property type | B2: text | C2: text | D2: Number | E2: Number | F2: Number | G2: Number | H2: List
A3: List of values (; separated) | H3: Yes, No
A4: Default value | B4: Wavefront sensors | C4: Beam Characterization
A5: Allow custom value
A6: Unit type | D6: nm | E6: nm | F6: nm (RMS) | G6: nm (RMS)
A7: Category group | B7: General properties | C7: General properties | D7: General properties | E7: General properties | F7: General properties | G7: General properties | H7: General properties

Sheet Catalogue items (1)
A1: Wavefront sensors
A2: =CONCATENATE('Catalogue properties'!B1," [",'Catalogue properties'!B6,"]") -> Catalogue Item name [] | B2: =CONCATENATE('Catalogue properties'!C1," [",'Catalogue properties'!C6,"]") -> Catalogue item description [] | C2: =CONCATENATE('Catalogue properties'!D1," [",'Catalogue properties'!D6,"]") -> Manufacturer [] | D2: =CONCATENATE('Catalogue properties'!E1," [",'Catalogue properties'!E6,"]") -> Manufacturer part/catalog number [] | E2: =CONCATENATE('Catalogue properties'!F1," [",'Catalogue properties'!F6,"]") -> ManufacturerURL [] | F2: =CONCATENATE('Wavefront Sensors'!D1," [",'Wavefront Sensors'!D6,"]") -> Wavelength range minimum [nm] | G2: =CONCATENATE('Wavefront Sensors'!E1," [",'Wavefront Sensors'!E6,"]") -> Wavelength range maximum [nm] | H2: =CONCATENATE('Wavefront Sensors'!F1," [",'Wavefront Sensors'!F6,"]") -> Accuracy [nm (RMS)] | I2: =CONCATENATE('Wavefront Sensors'!G1," [",'Wavefront Sensors'!G6,"]") -> Resolution [nm (RMS)] | J2: =CONCATENATE('Wavefront Sensors'!H1," [",'Wavefront Sensors'!H6,"]") -> Vacum compatible [] | K2: EUN
A3: SID4-HR | B3: The SID4-HR brings ultra-high phase sampling (400 x 300) and high dynamic range (500 µm PV) to the most demanding wavefront measurement applications. Its large aperture and extreme wavefront sensitivity makes it perfectly suited to direct measurement of large diverging beams without relay optics. | C3: Phasics | D3: SID4-HR | E3: https://www.phasics.com/en/product/sid4-hr-wavefront-sensor/ | F3: 400 | G3: 1100 | H3: 15 | I3: 2 | J3: No | K3: 20080413 | L3: 20100303
A4: SID4 | B4: Our entry-level yet high-resolution wavefront sensor covering the visible and NIR range, the SID4 is the perfect versatile tool for any laser or optical metrology application | C4: Phasics | D4: SID4 | E4: https://www.phasics.com/en/product/sid4-wavefront-sensor/ | F4: 400 | G4: 1100 | H4: 10 | I4: 2 | J4: No | K4: 16060195 | L4: 16080123 | M4: 16080124 | N4: 19110676 | O4: 21110005
A5: SHSLab AR-110-GE-PRO (central wavelength 820 nm) | B5: The all-purpose tool for testing optics and laser beams. Made up of the sensor head SHSCam and Optocraft’s powerful evaluation software SHSWorks. | C5: Optocraft | D5: obsolete | E5: https://www.optocraft.de/en/shslab/ | F5: 740 | G5: 1100 | I5: 110000 | J5: No | K5: 16080112-28 | L5: 16080138
A6: SHSLab AR-110-GE-PRO (central wavelength 410 nm) | B6: The all-purpose tool for testing optics and laser beams. Made up of the sensor head SHSCam and Optocraft’s powerful evaluation software SHSWorks. | C6: Optocraft | D6: obsolete | E6: https://www.optocraft.de/en/shslab/ | F6: 270 | G6: 550 | I6: 110000 | J6: No | K6: 16020134
A7: SHSCam BR-130-GE | B7: The all-purpose tool for testing optics and laser beams. Made up of the sensor head SHSCam and Optocraft’s powerful evaluation software SHSWorks. | C7: Optocraft | D7: obsolete | E7: https://www.optocraft.de/en/shslab/ | J7: No | K7: 15070018

Sheet Energy meters
A1: Property name | B1: Category | C1: Parent category | D1: Sensor type | E1: Energy range minimum | F1: Energy range maximum | G1: Resolution | H1: Aperture size | I1: Wavelength range | J1: Maximum repetition rate
A2: Property type | B2: text | C2: text | D2: Number | E2: Number | F2: Number | G2: Number | H2: Number | I2: List | J2: Number
A3: List of values (; separated)
A4: Default value | B4: Energy meters | C4: Beam Characterization
A5: Allow custom value
A6: Unit type | E6: mJ | F6: mJ | G6: uJ | H6: mm | J6: Hz
A7: Category group | B7: General properties | C7: General properties | D7: Energy Sensor | E7: Energy Sensor | F7: Energy Sensor | G7: Energy Sensor | H7: Energy Sensor | I7: General properties | J7: General properties

Sheet Catalogue items (2)
A1: Energy meters
A2: =CONCATENATE('Catalogue properties'!B1," [",'Catalogue properties'!B6,"]") -> Catalogue Item name [] | B2: =CONCATENATE('Catalogue properties'!C1," [",'Catalogue properties'!C6,"]") -> Catalogue item description [] | C2: =CONCATENATE('Catalogue properties'!D1," [",'Catalogue properties'!D6,"]") -> Manufacturer [] | D2: =CONCATENATE('Catalogue properties'!E1," [",'Catalogue properties'!E6,"]") -> Manufacturer part/catalog number [] | E2: =CONCATENATE('Catalogue properties'!F1," [",'Catalogue properties'!F6,"]") -> ManufacturerURL [] | F2: =CONCATENATE('Energy meters'!D1," [",'Energy meters'!D6,"]") -> Sensor type [] | G2: =CONCATENATE('Energy meters'!E1," [",'Energy meters'!E6,"]") -> Energy range minimum [mJ] | H2: =CONCATENATE('Energy meters'!F1," [",'Energy meters'!F6,"]") -> Energy range maximum [mJ] | I2: =CONCATENATE('Energy meters'!G1," [",'Energy meters'!G6,"]") -> Resolution [uJ] | J2: =CONCATENATE('Energy meters'!H1," [",'Energy meters'!H6,"]") -> Aperture size [mm] | K2: =CONCATENATE('Energy meters'!I1," [",'Energy meters'!I6,"]") -> Wavelength range [] | L2: =CONCATENATE('Energy meters'!J1," [",'Energy meters'!J6,"]") -> Maximum repetition rate [Hz] | M2: EUN
A3: QE25LP-S-MB-D0 | B3: Pyroelectric detector for laser energy measurement up to 3.8 J. | C3: LASER COMPONENTS GmbH | D3: P/N 200455 | E3: https://www.gentec-eo.com/products/qe25lp-s-mb-d0 | F3: Pyroelectric | H3: 3800 | I3: 4 | J3: 25 | K3: 0.193 - 20 μm | L3: 300 | M3: 21110401 | N3: 19040337
A4: QE65LP-S-MB-QED-INT-D0 | B4: Pyroelectric detector for laser energy measurement up to 200 J. With INTEGRA (USB) module. | C4: LASER COMPONENTS GmbH | D4: P/N 202768 | E4: https://www.gentec-eo.com/products/qe65lp-s-mb-qed-d0?ext=INTEGRA%20%28USB%29 | F4: Pyroelectric | H4: 2000 | I4: 20 | J4: 62 | K4: 0.3 - 2.1 μm | L4: 100 | M4: 21100038
A5: QE50LP-S-MB-QED-D0 | B5: Pyroelectric detector for laser energy measurement up to 85 J. | C5: LASER COMPONENTS GmbH | D5: P/N 202186 | E5: https://www.gentec-eo.com/products/qe50lp-s-mb-qed-d0 | F5: Pyroelectric | H5: 85000 | I5: 20 | J5: 47 | K5: 0.3 - 2.1 μm | L5: 200 | M5: 20060104 | N5: 19040338 | O5: 19040336
A6: Centauri Dual Channel | B6: High End Laser Power/Energy Meter Compatible with all standard Ophir Thermal, BeamTrack, Pyroelectric and Photodiode sensors for laser measuring | C6: Ophir | D6: P/N 7Z01701 | E6: https://www.ophiropt.com/laser--measurement/laser-power-energy-meters/products/laser-power-meters/centauri-dual-channel | M6: 20020448
A7: Centauri Single Channel | B7: High End Laser Power/Energy Meter Compatible with all standard Ophir Thermal, BeamTrack, Pyroelectric and Photodiode sensors for laser measuring | C7: Ophir | D7: P/N 7Z01700 | E7: https://www.ophiropt.com/laser--measurement/laser-power-energy-meters/products/laser-power-meters/centauri | M7: 21060062
A8: Laser Energy Sensor PE25-C | B8: The PE25-C is a general purpose pyroelectric energy meter with a 24mm aperture. It can measure energies from 8µJ up to 10J. It can operate at repetition rates up to 10kHz and covers the spectral range from 0.15 - 3µm. The sensor comes with a standard 1.5 meter cable for connecting to a meter or PC interface. | C8: Ophir | D8: P/N 7Z02937 | E8: https://www.ophiropt.com/laser--measurement/laser-power-energy-meters/products/Laser-Pyroelectric-Energy-Sensors/Pyroelectric-Laser-Energy-Sensors/PE25-C | F8: Pyroelectric | H8: 10000 | I8: 20 | J8: 24 | K8: 0.15-3µm | L8: 10000 | M8: 20020482 | N8: 21020279
A9: Vega | B9: Color Screen Handheld Laser Power & Energy Meter | C9: Ophir | D9: P/N 7Z01560 | E9: https://www.ophiropt.com/laser--measurement/laser-power-energy-meters/products/smart-displays/vega | M9: 20020483 | N9: 21020280 | O9: 21060061 | P9: 19110566 | Q9: 15060010 | R9: 19010106
A10: PE10-C | B10: The PE10-C is a pyroelectric energy meter for low energies with a 10mm aperture. It can measure energies from 1µJ up to 10mJ. It can operate at repetition rates up to 25kHz and covers the spectral range from 0.15 - 12µm. The sensor comes with a standard 1.5 meter cable for connecting to a meter or PC interface. | C10: Ophir | D10: P/N 7Z02932 | E10: https://www.ophiropt.com/laser--measurement/laser-power-energy-meters/products/Laser-Pyroelectric-Energy-Sensors/Pyroelectric-Laser-Energy-Sensors/PE10-C | F10: Pyroelectric | G10: 0.001 | H10: 10 | J10: 12 | K10: 0.15-12µm | L10: 25000 | M10: 14060565 | N10: 15060009 | O10: 19010103
A11: PE25-C | B11: The PE25-C is a general purpose pyroelectric energy meter with a 24mm aperture. It can measure energies from 8µJ up to 10J. It can operate at repetition rates up to 10kHz and covers the spectral range from 0.15 - 3µm. The sensor comes with a standard 1.5 meter cable for connecting to a meter or PC interface. | C11: Ophir | D11: P/N 7Z02937 | E11: https://www.ophiropt.com/laser--measurement/laser-power-energy-meters/products/Laser-Pyroelectric-Energy-Sensors/Pyroelectric-Laser-Energy-Sensors/PE25-C | F11: Pyroelectric | G11: 0.008 | H11: 10000 | J11: 24 | K11: 0.15-3µm | L11: 10000 | M11: 15060008 | N11: 17080014 | O11: 19010104 | P11: 20110078
A12: PE50-C | B12: The PE50-C is a general purpose pyroelectric energy meter with a 46mm aperture. It can measure energies from 10µJ up to 10J. It can operate at repetition rates up to 10kHz and covers the spectral range from 0.15 - 3µm. The sensor comes with a standard 1.5 meter cable for connecting to a meter or PC interface. | C12: Ophir | D12: P/N 7Z02936 | E12: https://www.ophiropt.com/laser--measurement/laser-power-energy-meters/products/Laser-Pyroelectric-Energy-Sensors/Pyroelectric-Laser-Energy-Sensors/PE50-C | F12: Pyroelectric | G12: 0.01 | H12: 10000 | J12: 46 | K12: 0.15-3µm | L12: 10000 | M12: 19010101
A13: PD300-1W | B13: The PD300-1W is a photodiode laser measurement sensor measuring to 1W. It has a 10x10mm aperture with swivel mount and a removable filter. Without filter, its spectral range is 350 - 1100nm and its power measuring range is 500pW - 30mW. With filter the spectral range is 430nm - 1100nm and the power range is 200µW - 1W. It has the exclusive Ophir automatic background subtraction feature. The sensor comes with a 1.5 meter cable for connecting to a meter or PC interface. | C13: Ophir | D13: P/N 7Z02411A | E13: https://www.ophiropt.com/laser--measurement/laser-power-energy-meters/products/Laser-Photodiode-Sensors/Standard-Photodiode-Sensors/PD300-1W | F13: Photodiode | H13: 0.2 | J13: 10 | K13: 350-1100nm | M13: 15060020
A14: PD300-3W | B14: The PD300-3W is a photodiode laser measurement sensor measuring to 3W. It has a 10x10mm aperture with swivel mount and a removable filter. Without filter, its spectral range is 350 - 1100nm and its power measuring range is 5nW - 100mW. With filter the spectral range is 430nm - 1100nm and the power range is 200µW to 3W. The sensor comes with a 1.5 meter cable for connecting to a meter or PC interface. | C14: Ophir | D14: P/N 7Z02426 | E14: https://www.ophiropt.com/laser--measurement/laser-power-energy-meters/products/Laser-Photodiode-Sensors/Standard-Photodiode-Sensors/PD300-3W | F14: Photodiode | H14: 0.4 | J14: 10 | K14: 350-1100nm | M14: 17080013 | N14: 19010101
A15: Pulsar-2 | B15: Ophir’s 2 channel Pulsar interface turns your PC or laptop into a full fledged Ophir multi-channel laser power/energy meter. Just install the software, plug the laser measurement sensor into the Pulsar and the USB cable from the Pulsar to the PC USB port. With the Pulsar-2, you can connect up to 2 laser measurement sensors to each module, monitor each pulse at up to 25 kHz and utilize external trigger. | C15: Ophir | D15: P/N 7Z01202 | E15: https://www.ophiropt.com/laser--measurement/laser-power-energy-meters/products/PC-Interfaces/Pulsar-2 | M15: 19010107
A16: L2000W-BB-120 | B16: The L2000W-BB-120 is a water cooled thermal power/energy laser measurement sensor with the very large aperture of 120mm. It can measure power from 1W to 2000W and energy from 6J to 6000J. It has the spectrally flat broadband coating and covers the spectral range from 0.19 to 20µm. The sensor comes with a standard 1.5 meter cable for connecting to a meter or PC interface. | C16: Ophir | D16: P/N 7Z02751 | E16: https://www.ophiropt.com/laser--measurement/laser-power-energy-meters/products/Laser-Thermal-Power-Sensors/High-Power-Water-Cooled-Thermal-Sensors-And-Power-Pucks/L2000W-BB-120 | F16: Thermal | G16: 6000 | H16: 6000000 | J16: 120 | K16: 0.19-20µm | M16: 19010108
A17: L50(300)A-PF-65 | B17: The L50(300)A-PF-65 is a thermal power/energy laser measurement sensor for high peak power pulsed lasers. It has a 65mm aperture and can measure from 400mW to 300W intermittently and to 50W continuously. It measures energy from 200mJ to 300J. It has a damage threshold of up to 3J/cm² for ns pulses and covers the spectral range from 0.15 to 20µm. The sensor comes with a standard 1.5 meter cable for connecting to a meter or PC interface. | C17: Ophir | D17: P/N 7Z02743 | E17: https://www.ophiropt.com/laser--measurement/laser-power-energy-meters/products/Laser-Thermal-Power-Sensors/Medium-Power-Thermal-Sensors/L50%28300%29A-PF-65 | F17: Thermal | G17: 200 | H17: 300000 | J17: 65 | K17: 0.15-20µm | M17: 19010098
A18: L250W | B18: The L250W is a water cooled low profile thermal power/energy laser measurement sensor with a 50mm aperture. It can measure power from 1W to 250W and energy from 120mJ to 300J. It has the spectrally flat broadband coating and covers the spectral range from 0.19 to 20µm. The sensor comes with a standard 1.5 meter cable for connecting to a meter or PC interface. | C18: Ophir | D18: P/N 7Z02688 | E18: https://www.ophiropt.com/laser--measurement/laser-power-energy-meters/products/Laser-Thermal-Power-Sensors/High-Power-Water-Cooled-Thermal-Sensors-And-Power-Pucks/L250W | F18: Thermal | G18: 120 | H18: 200000 | J18: 50 | K18: 0.19-20µm | M18: 19010099
A19: 30A-P-17 | B19: The 30A-P-17 is a thermal power/energy laser measurement sensor for short pulsed lasers with a 17mm aperture. It can measure from 60mW to 30W and from 40mJ to 30J. It has the P type volume absorber and covers the spectral range from 0.15 to 8µm. The sensor comes with a standard 1.5 meter cable for connecting to a meter or PC interface. | C19: Ophir | D19: P/N 7Z02693 | E19: https://www.ophiropt.com/laser--measurement/laser-power-energy-meters/products/Laser-Thermal-Power-Sensors/Low-Power-Thermal-Sensors/30A-P-17 | F19: Thermal | G19: 40 | H19: 30000 | J19: 17 | K19: 0.15-8µm | M19: 19010100
A20: PM150-19C | B20: PowerMax od Coherent jsou senzory pro měření výkonu kontinuálních laserů a nebo pulsních laserů s dlouhými pulsy. Termofilní senzory využívají principu termočlánku, kdy na absorbční vrstvu dopadá laserové záření, které je měněno v teplo. Mezi touto absorbční vrstvou a chladičem pak vzniká elektrické napětí. | C20: Coherent | D20: PM150-19C | E20: https://www.optixs.cz/doplnky-a-prislusenstvi--39k/mereni-vykonu-laseru-99k/termofilni-senzory-do-300w-133p | F20: Thermal | G20: 1000 | H20: 150000 | J20: 19 | K20: 0.25- 11µm | M20: 20110215
